Workbook

Sheet Jawaban Data Karyawan
A1: SOAL TES MASUK KERJA FORMAT SLIP GAJI
A4: NIK | B4: Nama | C4: Posisi | D4: Gaji Pokok | E4: Bonus | F4: BPJS Ketenagakerjaan | H4: BPJS Kesehatan | J4: Bonus PPh21 | K4: Bonus Transport | L4: Cicilan
F5: Perusahaan | G5: Karyawan | H5: Perusahaan | I5: Karyawan
A6: K01 | B6: Agus | C6: Pemasaran | D6: =VLOOKUP(C6,$B$21:$C$24,2,0) -> 4200000 | E6: =IF(C6="Direksi",3000000,IF(C6="Personalia",1000000,IF(C6="Pemasaran",500000,0))) -> 500000 | F6: =7%*D6 -> 294000 | G6: =5%*D6 -> 210000 | H6: =3%*D6 -> 126000 | I6: =2%*D6 -> 84000 | J6: =8%*D6 -> 336000 | K6: =IF(C6="Direksi",6%*D6,IF(C6="Personalia",4%*D6,0%)) -> 0 | L6: 898576
A7: K02 | B7: Susi | C7: Direksi | D7: =VLOOKUP(C7,$B$21:$C$24,2,0) -> 7000000 | E7: =IF(C7="Direksi",3000000,IF(C7="Personalia",1000000,IF(C7="Pemasaran",500000,0))) -> 3000000 | F7: =7%*D7 -> 490000 | G7: =5%*D7 -> 350000 | H7: =3%*D7 -> 210000 | I7: =2%*D7 -> 140000 | J7: =8%*D7 -> 560000 | K7: =IF(C7="Direksi",6%*D7,IF(C7="Personalia",4%*D7,0%)) -> 420000 | L7: 669771
A8: K03 | B8: Zahra | C8: Pemasaran | D8: =VLOOKUP(C8,$B$21:$C$24,2,0) -> 4200000 | E8: =IF(C8="Direksi",3000000,IF(C8="Personalia",1000000,IF(C8="Pemasaran",500000,0))) -> 500000 | F8: =7%*D8 -> 294000 | G8: =5%*D8 -> 210000 | H8: =3%*D8 -> 126000 | I8: =2%*D8 -> 84000 | J8: =8%*D8 -> 336000 | K8: =IF(C8="Direksi",6%*D8,IF(C8="Personalia",4%*D8,0%)) -> 0 | L8: 154626
A9: K04 | B9: Faiz | C9: Personalia | D9: =VLOOKUP(C9,$B$21:$C$24,2,0) -> 5500000 | E9: =IF(C9="Direksi",3000000,IF(C9="Personalia",1000000,IF(C9="Pemasaran",500000,0))) -> 1000000 | F9: =7%*D9 -> 385000 | G9: =5%*D9 -> 275000 | H9: =3%*D9 -> 165000 | I9: =2%*D9 -> 110000 | J9: =8%*D9 -> 440000 | K9: =IF(C9="Direksi",6%*D9,IF(C9="Personalia",4%*D9,0%)) -> 220000 | L9: 809626
A10: K05 | B10: Salim | C10: Admin | D10: =VLOOKUP(C10,$B$21:$C$24,2,0) -> 4000000 | E10: =IF(C10="Direksi",3000000,IF(C10="Personalia",1000000,IF(C10="Pemasaran",500000,0))) -> 0 | F10: =7%*D10 -> 280000 | G10: =5%*D10 -> 200000 | H10: =3%*D10 -> 120000 | I10: =2%*D10 -> 80000 | J10: =8%*D10 -> 320000 | K10: =IF(C10="Direksi",6%*D10,IF(C10="Personalia",4%*D10,0%)) -> 0 | L10: 837807
A11: K06 | B11: Ani | C11: Pemasaran | D11: =VLOOKUP(C11,$B$21:$C$24,2,0) -> 4200000 | E11: =IF(C11="Direksi",3000000,IF(C11="Personalia",1000000,IF(C11="Pemasaran",500000,0))) -> 500000 | F11: =7%*D11 -> 294000 | G11: =5%*D11 -> 210000 | H11: =3%*D11 -> 126000 | I11: =2%*D11 -> 84000 | J11: =8%*D11 -> 336000 | K11: =IF(C11="Direksi",6%*D11,IF(C11="Personalia",4%*D11,0%)) -> 0 | L11: 610394
A12: K07 | B12: Syita | C12: Personalia | D12: =VLOOKUP(C12,$B$21:$C$24,2,0) -> 5500000 | E12: =IF(C12="Direksi",3000000,IF(C12="Personalia",1000000,IF(C12="Pemasaran",500000,0))) -> 1000000 | F12: =7%*D12 -> 385000 | G12: =5%*D12 -> 275000 | H12: =3%*D12 -> 165000 | I12: =2%*D12 -> 110000 | J12: =8%*D12 -> 440000 | K12: =IF(C12="Direksi",6%*D12,IF(C12="Personalia",4%*D12,0%)) -> 220000 | L12: 124279
A13: K08 | B13: Rama | C13: Pemasaran | D13: =VLOOKUP(C13,$B$21:$C$24,2,0) -> 4200000 | E13: =IF(C13="Direksi",3000000,IF(C13="Personalia",1000000,IF(C13="Pemasaran",500000,0))) -> 500000 | F13: =7%*D13 -> 294000 | G13: =5%*D13 -> 210000 | H13: =3%*D13 -> 126000 | I13: =2%*D13 -> 84000 | J13: =8%*D13 -> 336000 | K13: =IF(C13="Direksi",6%*D13,IF(C13="Personalia",4%*D13,0%)) -> 0 | L13: 361261
A14: K09 | B14: Maksum | C14: Admin | D14: =VLOOKUP(C14,$B$21:$C$24,2,0) -> 4000000 | E14: =IF(C14="Direksi",3000000,IF(C14="Personalia",1000000,IF(C14="Pemasaran",500000,0))) -> 0 | F14: =7%*D14 -> 280000 | G14: =5%*D14 -> 200000 | H14: =3%*D14 -> 120000 | I14: =2%*D14 -> 80000 | J14: =8%*D14 -> 320000 | K14: =IF(C14="Direksi",6%*D14,IF(C14="Personalia",4%*D14,0%)) -> 0 | L14: 162308
A15: K10 | B15: Zha | C15: Pemasaran | D15: =VLOOKUP(C15,$B$21:$C$24,2,0) -> 4200000 | E15: =IF(C15="Direksi",3000000,IF(C15="Personalia",1000000,IF(C15="Pemasaran",500000,0))) -> 500000 | F15: =7%*D15 -> 294000 | G15: =5%*D15 -> 210000 | H15: =3%*D15 -> 126000 | I15: =2%*D15 -> 84000 | J15: =8%*D15 -> 336000 | K15: =IF(C15="Direksi",6%*D15,IF(C15="Personalia",4%*D15,0%)) -> 0 | L15: 356221
A18: Tabel Acuan
A19: No. | B19: Posisi | C19: Gaji Pokok | D19: 0 = FALSE
D20: 1 = TRUE
A21: 1 | B21: Direksi | C21: 7000000
A22: 2 | B22: Personalia | C22: 5500000
A23: 3 | B23: Pemasaran | C23: 4200000
A24: 4 | B24: Admin | C24: 4000000
A27: PETUNJUK PENGISIAN:
A28: 1. Gaji Pokok : Menggunakan rumus Vlookup yang diambil dari Tabel Acuan
A29: 2. Bonus :
A30: - Direksi : Rp 3.000.000
A31: - Personalia : Rp 1.000.000
A32: - Pemasaran : Rp 500.000
A33: 3. BPJS Ketenagakerjaan :
A34: - Perusahaan : 7% dari Gaji Pokok
A35: - Karyawan : 5% dari Gaji Pokok
A36: 4. BPJS Kesehatan :
A37: - Perusahaan : 3% dari Gaji Pokok
A38: - Karyawan : 2% dari Gaji Pokok
... A42: - Personalia : 4% dari Gaji Pokok

Sheet Jawaban Slip Gaji
B2: SLIP GAJI BKDN SEJAHTERA
B4: NIK | C4: : | D4: K03
B5: Nama | C5: : | D5: =VLOOKUP(D4,'Jawaban Data Karyawan'!$A$6:$L$15,2,0) -> Zahra
B6: Posisi | C6: : | D6: =VLOOKUP(D4,'Jawaban Data Karyawan'!$A$6:$L$15,3,0) -> Pemasaran
B7: Tanggal | C7: : | D7: =TODAY() -> 46051
B9: DITERIMA | H9: DIPOTONG
B10: Gaji Pokok | E10: : | F10: =VLOOKUP(D4,'Jawaban Data Karyawan'!$A$6:$L$15,4,0) -> 4200000 | H10: PPh 21 | K10: : | L10: =VLOOKUP(D4,'Jawaban Data Karyawan'!$A$6:$L$15,10,0) -> 336000
B11: Bonus | E11: : | F11: =VLOOKUP(D4,'Jawaban Data Karyawan'!$A$6:$L$15,5,0) -> 500000 | H11: BPJS Ketenagakerjaan | K11: : | L11: =VLOOKUP(D4,'Jawaban Data Karyawan'!$A$6:$L$15,7,0) -> 210000
B12: BPJS Ketenagakerjaan | E12: : | F12: =VLOOKUP(D4,'Jawaban Data Karyawan'!$A$6:$L$15,6,0) -> 294000 | H12: BPJS Kesehatan | K12: : | L12: =VLOOKUP(D4,'Jawaban Data Karyawan'!$A$6:$L$15,9,0) -> 84000
B13: BPJS Kesehatan | E13: : | F13: =VLOOKUP(D4,'Jawaban Data Karyawan'!$A$6:$L$15,8,0) -> 126000 | H13: Cicilan | K13: : | L13: =VLOOKUP(D4,'Jawaban Data Karyawan'!$A$6:$L$15,12,0) -> 154626
B14: PPh 21 | E14: : | F14: =VLOOKUP(D4,'Jawaban Data Karyawan'!$A$6:$L$15,10,0) -> 336000
B15: Bonus Transport | E15: : | F15: =VLOOKUP(D4,'Jawaban Data Karyawan'!$A$6:$L$15,11,0) -> 0
B17: Total Penerimaan | E17: : | F17: =SUM(F10:G15) -> 5456000 | H17: Total Potongan | K17: : | L17: =SUM(L10:M13) -> 784626
B19: Gaji Bersih | K19: : | L19: =F17-L17 -> 4671374
B20: Terbilang | H20: Empat Juta Enam Ratus Tujuh Puluh Satu Ribu Tiga Ratus Tujuh Puluh Empat Rupiah
B23: SLIP GAJI BKDN SEJAHTERA
B25: NIK | C25: : | D25: K04
B26: Nama | C26: : | D26: =VLOOKUP(D25,'Jawaban Data Karyawan'!$A$6:$L$15,2,0) -> Faiz
B27: Posisi | C27: : | D27: =VLOOKUP(D25,'Jawaban Data Karyawan'!$A$6:$L$15,3,0) -> Personalia
B28: Tanggal | C28: : | D28: =TODAY() -> 46051
B30: DITERIMA | H30: DIPOTONG
B31: Gaji Pokok | E31: : | F31: =VLOOKUP(D25,'Jawaban Data Karyawan'!$A$6:$L$15,4,0) -> 5500000 | H31: PPh 21 | K31: : | L31: =VLOOKUP(D25,'Jawaban Data Karyawan'!$A$6:$L$15,10,0) -> 440000
B32: Bonus | E32: : | F32: =VLOOKUP(D25,'Jawaban Data Karyawan'!$A$6:$L$15,5,0) -> 1000000 | H32: BPJS Ketenagakerjaan | K32: : | L32: =VLOOKUP(D25,'Jawaban Data Karyawan'!$A$6:$L$15,7,0) -> 275000
B33: BPJS Ketenagakerjaan | E33: : | F33: =VLOOKUP(D25,'Jawaban Data Karyawan'!$A$6:$L$16,6,0) -> 385000 | H33: BPJS Kesehatan | K33: : | L33: =VLOOKUP(D25,'Jawaban Data Karyawan'!$A$6:$L$15,9,) -> 110000
B34: BPJS Kesehatan | E34: : | F34: =VLOOKUP(D25,'Jawaban Data Karyawan'!$A$6:$L$15,8,0) -> 165000 | H34: Cicilan | K34: : | L34: =VLOOKUP(D25,'Jawaban Data Karyawan'!$A$6:$L$15,12,0) -> 809626
B35: PPh 21 | E35: : | F35: =VLOOKUP(D25,'Jawaban Data Karyawan'!$A$6:$L$15,10,0) -> 440000
B36: Bonus Transport | E36: : | F36: =VLOOKUP(D25,'Jawaban Data Karyawan'!$A$6:$L$15,11,0) -> 220000
B38: Total Penerimaan | E38: : | F38: =SUM(F31:G36) -> 7710000 | H38: Total Potongan | K38: : | L38: =SUM(L31:M34) -> 1634626
B40: Gaji Bersih | K40: : | L40: =F38-L38 -> 6075374
B41: Terbilang | H41: Enam Juta Tujuh Puluh Lima Ribu Tiga Ratus Tujuh Puluh Empat Rupiah
B45: SLIP GAJI BKDN SEJAHTERA
B47: NIK | C47: : | D47: K02
B48: Nama | C48: : | D48: =VLOOKUP(D47,'Jawaban Data Karyawan'!$A$6:$L$15,2,0) -> Susi
B49: Posisi | C49: : | D49: =VLOOKUP(D47,'Jawaban Data Karyawan'!$A$6:$L$15,3,0) -> Direksi
B50: Tanggal | C50: : | D50: =TODAY() -> 46051
B52: DITERIMA | H52: DIPOTONG
B53: Gaji Pokok | E53: : | F53: =VLOOKUP(D47,'Jawaban Data Karyawan'!$A$6:$L$15,4,0) -> 7000000 | H53: PPh 21 | K53: : | L53: =VLOOKUP(D47,'Jawaban Data Karyawan'!$A$6:$L$15,10,0) -> 560000
B54: Bonus | E54: : | F54: =VLOOKUP(D47,'Jawaban Data Karyawan'!$A$6:$L$15,5,0) -> 3000000 | H54: BPJS Ketenagakerjaan | K54: : | L54: =VLOOKUP(D47,'Jawaban Data Karyawan'!$A$6:$L$15,7,0) -> 350000
B55: BPJS Ketenagakerjaan | E55: : | F55: =VLOOKUP(D47,'Jawaban Data Karyawan'!$A$6:$L$15,6,0) -> 490000 | H55: BPJS Kesehatan | K55: : | L55: =VLOOKUP(D47,'Jawaban Data Karyawan'!$A$6:$L$15,9,0) -> 140000
B56: BPJS Kesehatan | E56: : | F56: =VLOOKUP(D47,'Jawaban Data Karyawan'!$A$6:$L$15,8,0) -> 210000 | H56: Cicilan | K56: : | L56: =VLOOKUP(D47,'Jawaban Data Karyawan'!$A$6:$L$15,12,0) -> 669771
...

Sheet Soal Data Karyawan
A1: SOAL TES MASUK KERJA FORMAT SLIP GAJI
A4: NIK | B4: Nama | C4: Posisi | D4: Gaji Pokok | E4: Bonus | F4: BPJS Ketenagakerjaan | H4: BPJS Kesehatan | J4: Bonus PPh21 | K4: Bonus Transport | L4: Cicilan
F5: Perusahaan | G5: Karyawan | H5: Perusahaan | I5: Karyawan
A6: K01 | B6: Agus | C6: Pemasaran | L6: 898576
A7: K02 | B7: Susi | C7: Direksi | L7: 669771
A8: K03 | B8: Zahra | C8: Pemasaran | L8: 154626
A9: K04 | B9: Faiz | C9: Personalia | L9: 809626
A10: K05 | B10: Salim | C10: Admin | L10: 837807
A11: K06 | B11: Ani | C11: Pemasaran | L11: 610394
A12: K07 | B12: Syita | C12: Personalia | L12: 124279
A13: K08 | B13: Rama | C13: Pemasaran | L13: 361261
A14: K09 | B14: Maksum | C14: Admin | L14: 162308
A15: K10 | B15: Zha | C15: Pemasaran | L15: 356221
A18: Tabel Acuan
A19: No. | B19: Posisi | C19: Gaji Pokok | D19: 0 = FALSE
D20: 1 = TRUE
A21: 1 | B21: Direksi | C21: 7000000
A22: 2 | B22: Personalia | C22: 5500000
A23: 3 | B23: Pemasaran | C23: 4200000
A24: 4 | B24: Admin | C24: 4000000
A27: PETUNJUK PENGISIAN:
A28: 1. Gaji Pokok : Menggunakan rumus Vlookup yang diambil dari Tabel Acuan
A29: 2. Bonus :
A30: - Direksi : Rp 3.000.000
A31: - Personalia : Rp 1.000.000
A32: - Pemasaran : Rp 500.000
A33: 3. BPJS Ketenagakerjaan :
A34: - Perusahaan : 7% dari Gaji Pokok
A35: - Karyawan : 5% dari Gaji Pokok
A36: 4. BPJS Kesehatan :
A37: - Perusahaan : 3% dari Gaji Pokok
A38: - Karyawan : 2% dari Gaji Pokok
... A42: - Personalia : 4% dari Gaji Pokok

Sheet Soal Slip Gaji
Q1: (silahkan bisa dilanjutkan lagi untuk slip gaji, bisa di copy-paste untuk formatnya)
B2: SLIP GAJI BKDN SEJAHTERA
B4: NIK | C4: : | D4: K03
B5: Nama | C5: : | D5: =VLOOKUP(D4,'Jawaban Data Karyawan'!$A$6:$L$15,2,0) -> Zahra
B6: Posisi | C6: : | D6: =VLOOKUP(D4,'Jawaban Data Karyawan'!$A$6:$L$15,3,0) -> Pemasaran
B7: Tanggal | C7: : | D7: =TODAY() -> 46051
B9: DITERIMA | H9: DIPOTONG
B10: Gaji Pokok | E10: : | H10: PPh 21 | K10: :
B11: Bonus | E11: : | H11: BPJS Ketenagakerjaan | K11: :
B12: BPJS Ketenagakerjaan | E12: : | H12: BPJS Kesehatan | K12: :
B13: BPJS Kesehatan | E13: : | H13: Cicilan | K13: :
B14: PPh 21 | E14: :
B15: Bonus Transport | E15: :
B17: Total Penerimaan | E17: : | H17: Total Potongan | K17: :
B19: Gaji Bersih | K19: :
B20: Terbilang
